<mujoco model="Rizon4s">
  <option iterations="50" timestep="0.001" solver="PGS" gravity="0 0 -9.81" />

  <compiler angle="radian" meshdir="meshes/Rizon4s" eulerseq="zyx" autolimits="true" />

  <default>
    <joint limited="true" damping="0.01" armature="0.01" frictionloss="0.01" />
    <geom condim="4" contype="1" conaffinity="15" friction="0.9 0.2 0.2" solref="0.001 2" />
    <motor ctrllimited="true" />
    <equality solref="0.001 2" />
    <default class="visualgeom">
      <geom material="visualgeom" condim="1" contype="0" conaffinity="0" />
    </default>
  </default>

  <asset>
    <mesh name="link0_visual" file="visual/link0.obj" />
    <mesh name="link1_visual" file="visual/link1.obj" />
    <mesh name="link2_visual" file="visual/link2.obj" />
    <mesh name="link3_visual" file="visual/link3.obj" />
    <mesh name="link4_visual" file="visual/link4.obj" />
    <mesh name="link5_visual" file="visual/link5.obj" />
    <mesh name="link6_visual" file="visual/link6.obj" />
    <mesh name="link7_visual" file="visual/link7.obj" />
    <mesh name="ring_visual_062" file="visual/ring.obj" scale="0.062 0.062 0.002" />
    <mesh name="ring_visual_051" file="visual/ring.obj" scale="0.051 0.051 0.002" />
    <mesh name="link0_collision" file="collision/link0.stl" />
    <mesh name="link1_collision" file="collision/link1.stl" />
    <mesh name="link2_collision" file="collision/link2.stl" />
    <mesh name="link3_collision" file="collision/link3.stl" />
    <mesh name="link4_collision" file="collision/link4.stl" />
    <mesh name="link5_collision" file="collision/link5.stl" />
    <mesh name="link6_collision" file="collision/link6.stl" />
    <mesh name="link7_collision" file="collision/link7.stl" />
    <texture name="texplane" type="2d" builtin="checker" rgb1=".0 .0 .0" rgb2=".8 .8 .8" width="100" height="100" />
    <material name="matplane" reflectance="0." texture="texplane" texrepeat="1 1" texuniform="true" />
    <material name="visualgeom" rgba="0.6 0.6 0.6 1"/>
    <material name="ring_material" rgba="0.49 0.678 0.8 1"/>
  </asset>

  <worldbody>
    <light directional="true" diffuse="0.4 0.4 0.4" specular="0.1 0.1 0.1" pos="0 0 5.0" dir="0 0 -1" castshadow="false" />
    <light directional="true" diffuse="0.6 0.6 0.6" specular="0.2 0.2 0.2" pos="0 0 4" dir="0 0 -1" />
    <!-- <geom name="ground" type="plane" pos="0 0 0" size="100 100 0.001" quat="1 0 0 0" material="matplane" condim="3" conaffinity="15" /> -->
    <camera name="fixed" pos="0 -3.0 0.517318010072385" xyaxes="1 0 0 0 0 1" />
    <body name="root" pos="0 0 0" quat="1 0 0 0">
      <site name="imu" size="0.01" pos="0 0 0" />
      <geom type="mesh" mesh="link0_visual" class="visualgeom" />
      <geom type="mesh" mesh="link0_collision" rgba="0 0 0 0" />
      <body name="link1" pos="0 0 0.155" quat="0 0 0 -1">
        <inertial pos="0 0 0.15" mass="3.6" diaginertia="0.03 0.03 0.01" />
        <joint name="joint1" pos="0 0 0" axis="0 0 1" range="-2.8798 2.8798" actuatorfrcrange="-123 123" />
        <geom type="mesh" mesh="link1_visual" class="visualgeom" />
        <geom type="mesh" mesh="ring_visual_062" class="visualgeom" pos="0 0 -0.0025" material="ring_material"/>
        <geom type="mesh" mesh="link1_collision" rgba="0 0 0 0" />
        <body name="link2" pos="0 0.03 0.21">
          <inertial pos="0 0.04 0.1" mass="2.7" diaginertia="0.02 0.02 0.01" />
          <joint name="joint2" pos="0 0 0" axis="0 1 0" range="-2.3562 2.3562" actuatorfrcrange="-123 123" />
          <geom type="mesh" mesh="link2_visual" class="visualgeom" />
          <geom type="mesh" mesh="ring_visual_062" class="visualgeom" pos="0 -0.0025 0" quat="0.7071068 0.7071068 0 0" material="ring_material"/>
          <geom type="mesh" mesh="link2_collision" rgba="0 0 0 0" />
          <body name="link3" pos="0 0.035 0.205">
            <inertial pos="-0.01 0 0.14" mass="2.4" diaginertia="0.01 0.01 0.01" />
            <joint name="joint3" pos="0 0 0" axis="0 0 1" range="-3.0543 3.0543" actuatorfrcrange="-64 64" />
            <geom type="mesh" mesh="link3_visual" class="visualgeom" />
            <geom type="mesh" mesh="ring_visual_051" class="visualgeom" pos="0 0 -0.0025" material="ring_material"/>
            <geom type="mesh" mesh="link3_collision" rgba="0 0 0 0" />
            <body name="link4" pos="-0.02 -0.03 0.19" quat="0 0 0 -1">
              <inertial pos="-0.01 0.03 0.1" mass="2.4" diaginertia="0.02 0.02 0.01" />
              <joint name="joint4" pos="0 0 0" axis="0 1 0" range="-1.9548 2.7751" actuatorfrcrange="-64 64" />
              <geom type="mesh" mesh="link4_visual" class="visualgeom" />
              <geom type="mesh" mesh="ring_visual_051" class="visualgeom" pos="0 -0.0025 0" quat="0.7071068 0.7071068 0 0" material="ring_material"/>
              <geom type="mesh" mesh="link4_collision" rgba="0 0 0 0" />
              <body name="link5" pos="-0.02 0.025 0.195" quat="0 0 0 -1">
                <inertial pos="0 0 0.14" mass="2.3" diaginertia="0.01 0.01 0.01" />
                <joint name="joint5" pos="0 0 0" axis="0 0 1" range="-3.0543 3.0543" actuatorfrcrange="-39 39" />
                <geom type="mesh" mesh="link5_visual" class="visualgeom" />
                <geom type="mesh" mesh="ring_visual_051" class="visualgeom" pos="0 0 -0.0025" material="ring_material"/>
                <geom type="mesh" mesh="link5_collision" rgba="0 0 0 0" />
                <body name="link6" pos="0 0.03 0.19">
                  <inertial pos="0.02 0.06 0.07" mass="2.2" diaginertia="0.01 0.01 0.01" />
                  <joint name="joint6" pos="0 0 0" axis="0 1 0" range="-1.4835 4.6251" actuatorfrcrange="-39 39" />
                  <geom type="mesh" mesh="link6_visual" class="visualgeom" />
                  <geom type="mesh" mesh="ring_visual_051" class="visualgeom" pos="0 -0.0025 0" quat="0.7071068 0.7071068 0 0" material="ring_material"/>
                  <geom type="mesh" mesh="link6_collision" rgba="0 0 0 0" />
                  <body name="link7" pos="-0.015 0.073 0.11" quat="0.707107 0 -0.707107 0">
                    <inertial pos="0 0 0.0505248" mass="1.41" diaginertia="0.0200544 0.0200544 0.02" />
                    <joint name="joint7" pos="0 0 0" axis="0 0 1" range="-3.0543 3.0543" actuatorfrcrange="-39 39" />
                    <geom type="mesh" mesh="link7_visual" class="visualgeom" />
                    <geom type="mesh" mesh="ring_visual_051" class="visualgeom" pos="0 0 -0.0025" material="ring_material"/>
                    <geom type="mesh" mesh="link7_collision" rgba="0 0 0 0" />
                    <body name="flange" pos="0 0 0.124" quat="0 0 0 -1">
                      <inertial mass="0.0" pos="0 0 0" diaginertia="0 0 0" />
                    </body>
                  </body>
                </body>
              </body>
            </body>
          </body>
        </body>
      </body>
    </body>
  </worldbody>

  <keyframe>
    <key name="home" qpos="0 0 0 0 0 0 0" />
  </keyframe>

  <actuator>
    <position name="joint1" joint="joint1" forcerange="-123 123" kp="2500" kv="100" ctrlrange="-2.8798 2.8798"/>
    <position name="joint2" joint="joint2" forcerange="-123 123" kp="2500" kv="100" ctrlrange="-2.3562 2.3562"/>
    <position name="joint3" joint="joint3" forcerange="-64 64" kp="2500" kv="100" ctrlrange="-3.0543 3.0543"/>
    <position name="joint4" joint="joint4" forcerange="-64 64" kp="2500" kv="100" ctrlrange="-1.9548 2.7751"/>
    <position name="joint5" joint="joint5" forcerange="-39 39" kp="500" kv="25" ctrlrange="-3.0543 3.0543"/>
    <position name="joint6" joint="joint6" forcerange="-39 39" kp="500" kv="25" ctrlrange="-1.4835 4.6251"/>
    <position name="joint7" joint="joint7" forcerange="-39 39" kp="500" kv="25" ctrlrange="-3.0543 3.0543"/>
  </actuator>

  <sensor>
    <actuatorpos name="joint1_p" actuator="joint1" />
    <actuatorvel name="joint1_v" actuator="joint1" />
    <actuatorfrc name="joint1_f" actuator="joint1" noise="0.001" />
    <actuatorpos name="joint2_p" actuator="joint2" />
    <actuatorvel name="joint2_v" actuator="joint2" />
    <actuatorfrc name="joint2_f" actuator="joint2" noise="0.001" />
    <actuatorpos name="joint3_p" actuator="joint3" />
    <actuatorvel name="joint3_v" actuator="joint3" />
    <actuatorfrc name="joint3_f" actuator="joint3" noise="0.001" />
    <actuatorpos name="joint4_p" actuator="joint4" />
    <actuatorvel name="joint4_v" actuator="joint4" />
    <actuatorfrc name="joint4_f" actuator="joint4" noise="0.001" />
    <actuatorpos name="joint5_p" actuator="joint5" />
    <actuatorvel name="joint5_v" actuator="joint5" />
    <actuatorfrc name="joint5_f" actuator="joint5" noise="0.001" />
    <actuatorpos name="joint6_p" actuator="joint6" />
    <actuatorvel name="joint6_v" actuator="joint6" />
    <actuatorfrc name="joint6_f" actuator="joint6" noise="0.001" />
    <actuatorpos name="joint7_p" actuator="joint7" />
    <actuatorvel name="joint7_v" actuator="joint7" />
    <actuatorfrc name="joint7_f" actuator="joint7" noise="0.001" />
    <framequat name="orientation" objtype="site" noise="0.001" objname="imu" />
    <gyro name="angular-velocity" site="imu" noise="0.005" cutoff="34.9" />
  </sensor>
</mujoco>