<mujoco model="dual_ur5e">
    <compiler angle="radian" meshdir="assets" autolimits="true" eulerseq="zyx"/>

    <option integrator="implicitfast"/>

    <default>
        <default class="ur5e">
            <default class="visual">
                <geom type="mesh" contype="0" conaffinity="0" group="2"/>
            </default>
            <default class="collision">
                <geom type="capsule" group="3"/>
                <default class="eef_collision">
                    <geom type="cylinder"/>
                </default>
            </default>
            <joint axis="0 1 0" range="-6.28319 6.28319"/>
            <default class="joint_limited">
                <joint range="-3.1415 3.1415"/>
            </default>
            <default class="position">
                <position ctrlrange="-6.2831 6.2831" kp="2000" kv="100" forcerange="-150 150"/>
                <default class="position_limited">
                    <position ctrlrange="-3.1415 3.1415"/>
                </default>
                <default class="position_small">
                    <position kp="500" kv="25" forcerange="-28 28"/>
                </default>
            </default>
        </default>
    </default>

    <asset>
        <material name="black" rgba="0.033 0.033 0.033 1"/>
        <material name="jointgray" rgba="0.278 0.278 0.278 1"/>
        <material name="linkgray" rgba="0.82 0.82 0.82 1"/>
        <material name="urblue" rgba="0.49 0.678 0.8 1"/>

        <mesh file="base_0.obj"/>
        <mesh file="base_1.obj"/>
        <mesh file="shoulder_0.obj"/>
        <mesh file="shoulder_1.obj"/>
        <mesh file="shoulder_2.obj"/>
        <mesh file="upperarm_0.obj"/>
        <mesh file="upperarm_1.obj"/>
        <mesh file="upperarm_2.obj"/>
        <mesh file="upperarm_3.obj"/>
        <mesh file="forearm_0.obj"/>
        <mesh file="forearm_1.obj"/>
        <mesh file="forearm_2.obj"/>
        <mesh file="forearm_3.obj"/>
        <mesh file="wrist1_0.obj"/>
        <mesh file="wrist1_1.obj"/>
        <mesh file="wrist1_2.obj"/>
        <mesh file="wrist2_0.obj"/>
        <mesh file="wrist2_1.obj"/>
        <mesh file="wrist2_2.obj"/>
        <mesh file="wrist3.obj"/>
    </asset>

    <worldbody>
        <light diffuse=".5 .5 .5" pos="0 0 4" dir="0 0 -1"/>
        <!-- <geom name="floor" type="plane" size="3 3 0.1" rgba=".9 .9 .9 1"/> -->
        
        <!-- Common world frame named 'base' -->
        <body name="base" pos="0 0 0">
            <!-- Optional: a visual for the world base -->
            <!-- <geom type="sphere" size="0.05" rgba="0.5 0.5 0.5 0.5"/> -->
        </body>

        <!-- Left Arm -->
        <body name="left_robot_base" pos="0 0.275 0.3" quat="0 0 0.3826834 0.9238795" childclass="ur5e">
            <inertial mass="4" pos="0 0 0" diaginertia="0.00443333156 0.00443333156 0.0072"/>
            <geom mesh="base_0" material="black" class="visual"/>
            <geom mesh="base_1" material="jointgray" class="visual"/>
            <body name="left_shoulder_link" pos="0 0 0.163">
                <inertial mass="3.7" pos="0 0 0" diaginertia="0.0102675 0.0102675 0.00666"/>
                <joint name="left_shoulder_pan_joint" axis="0 0 1"/>
                <geom mesh="shoulder_0" material="urblue" class="visual"/>
                <geom mesh="shoulder_1" material="black" class="visual"/>
                <geom mesh="shoulder_2" material="jointgray" class="visual"/>
                <geom class="collision" size="0.06 0.06" pos="0 0 -0.04"/>
                <body name="left_upper_arm_link" pos="0 0.138 0" quat="1 0 1 0">
                    <inertial mass="8.393" pos="0 0 0.2125" diaginertia="0.133886 0.133886 0.0151074"/>
                    <joint name="left_shoulder_lift_joint"/>
                    <geom mesh="upperarm_0" material="linkgray" class="visual"/>
                    <geom mesh="upperarm_1" material="black" class="visual"/>
                    <geom mesh="upperarm_2" material="jointgray" class="visual"/>
                    <geom mesh="upperarm_3" material="urblue" class="visual"/>
                    <geom class="collision" pos="0 -0.04 0" quat="1 1 0 0" size="0.06 0.06"/>
                    <geom class="collision" size="0.05 0.2" pos="0 0 0.2"/>
                    <body name="left_forearm_link" pos="0 -0.131 0.425">
                        <inertial mass="2.275" pos="0 0 0.196" diaginertia="0.0311796 0.0311796 0.004095"/>
                        <joint name="left_elbow_joint" class="joint_limited"/>
                        <geom mesh="forearm_0" material="urblue" class="visual"/>
                        <geom mesh="forearm_1" material="linkgray" class="visual"/>
                        <geom mesh="forearm_2" material="black" class="visual"/>
                        <geom mesh="forearm_3" material="jointgray" class="visual"/>
                        <geom class="collision" pos="0 0.08 0" quat="1 1 0 0" size="0.055 0.06"/>
                        <geom class="collision" size="0.038 0.19" pos="0 0 0.2"/>
                        <body name="left_wrist_1_link" pos="0 0 0.392" quat="1 0 1 0">
                            <inertial mass="1.219" pos="0 0.127 0" diaginertia="0.0025599 0.0025599 0.0021942"/>
                            <joint name="left_wrist_1_joint"/>
                            <geom mesh="wrist1_0" material="black" class="visual"/>
                            <geom mesh="wrist1_1" material="urblue" class="visual"/>
                            <geom mesh="wrist1_2" material="jointgray" class="visual"/>
                            <geom class="collision" pos="0 0.05 0" quat="1 1 0 0" size="0.04 0.07"/>
                            <body name="left_wrist_2_link" pos="0 0.127 0">
                                <inertial mass="1.219" pos="0 0 0.1" diaginertia="0.0025599 0.0025599 0.0021942"/>
                                <joint name="left_wrist_2_joint" axis="0 0 1"/>
                                <geom mesh="wrist2_0" material="black" class="visual"/>
                                <geom mesh="wrist2_1" material="urblue" class="visual"/>
                                <geom mesh="wrist2_2" material="jointgray" class="visual"/>
                                <geom class="collision" size="0.04 0.06" pos="0 0 0.04"/>
                                <geom class="collision" pos="0 0.02 0.1" quat="1 1 0 0" size="0.04 0.04"/>
                                <body name="left_wrist_3_link" pos="0 0 0.1">
                                    <inertial mass="0.1879" pos="0 0.0771683 0" quat="1 0 0 1" diaginertia="0.000132134 9.90863e-05 9.90863e-05"/>
                                    <joint name="left_wrist_3_joint"/>
                                    <geom material="linkgray" mesh="wrist3" class="visual"/>
                                    <geom class="eef_collision" pos="0 0.08 0" quat="1 1 0 0" size="0.04 0.02"/>
                                    <site name="left_attachment_site" size="0.01" pos="0 0.1 0" quat="-1 1 1 1" rgba="1 0 0 1" group="1"/>
                                    <body name="left_tool0" pos="0 0.1 0" quat="0.70710678 -0.70710678 0 0">
                                        <geom name="left_tool0_x_shaft" type="cylinder" size="0.005 0.05" pos="0.05 0 0" zaxis="1 0 0" rgba="1 0 0 1" contype="0" conaffinity="0" group="1" class="visual"/>
                                        <geom name="left_tool0_y_shaft" type="cylinder" size="0.005 0.05" pos="0 0.05 0" zaxis="0 1 0" rgba="0 1 0 1" contype="0" conaffinity="0" group="1" class="visual"/>
                                        <geom name="left_tool0_z_shaft" type="cylinder" size="0.005 0.05" pos="0 0 0.05" zaxis="0 0 1" rgba="0 0 1 1" contype="0" conaffinity="0" group="1" class="visual"/>
                                        <site name="left_tool0_site" size="0.01" pos="0 0 0" rgba="0 1 0 1" group="1"/>
                                    </body>
                                </body>
                            </body>
                        </body>
                    </body>
                </body>
            </body>
        </body>
        <!-- Right Arm -->
        <body name="right_robot_base" pos="0 -0.275 0.3" quat="0.92387953 0.38268343 0. 0." childclass="ur5e">
            <inertial mass="4" pos="0 0 0" diaginertia="0.00443333156 0.00443333156 0.0072"/>
            <geom mesh="base_0" material="black" class="visual"/>
            <geom mesh="base_1" material="jointgray" class="visual"/>
            <body name="right_shoulder_link" pos="0 0 0.163">
                <inertial mass="3.7" pos="0 0 0" diaginertia="0.0102675 0.0102675 0.00666"/>
                <joint name="right_shoulder_pan_joint" axis="0 0 1"/>
                <geom mesh="shoulder_0" material="urblue" class="visual"/>
                <geom mesh="shoulder_1" material="black" class="visual"/>
                <geom mesh="shoulder_2" material="jointgray" class="visual"/>
                <geom class="collision" size="0.06 0.06" pos="0 0 -0.04"/>
                <body name="right_upper_arm_link" pos="0 0.138 0" quat="1 0 1 0">
                    <inertial mass="8.393" pos="0 0 0.2125" diaginertia="0.133886 0.133886 0.0151074"/>
                    <joint name="right_shoulder_lift_joint"/>
                    <geom mesh="upperarm_0" material="linkgray" class="visual"/>
                    <geom mesh="upperarm_1" material="black" class="visual"/>
                    <geom mesh="upperarm_2" material="jointgray" class="visual"/>
                    <geom mesh="upperarm_3" material="urblue" class="visual"/>
                    <geom class="collision" pos="0 -0.04 0" quat="1 1 0 0" size="0.06 0.06"/>
                    <geom class="collision" size="0.05 0.2" pos="0 0 0.2"/>
                    <body name="right_forearm_link" pos="0 -0.131 0.425">
                        <inertial mass="2.275" pos="0 0 0.196" diaginertia="0.0311796 0.0311796 0.004095"/>
                        <joint name="right_elbow_joint" class="joint_limited"/>
                        <geom mesh="forearm_0" material="urblue" class="visual"/>
                        <geom mesh="forearm_1" material="linkgray" class="visual"/>
                        <geom mesh="forearm_2" material="black" class="visual"/>
                        <geom mesh="forearm_3" material="jointgray" class="visual"/>
                        <geom class="collision" pos="0 0.08 0" quat="1 1 0 0" size="0.055 0.06"/>
                        <geom class="collision" size="0.038 0.19" pos="0 0 0.2"/>
                        <body name="right_wrist_1_link" pos="0 0 0.392" quat="1 0 1 0">
                            <inertial mass="1.219" pos="0 0.127 0" diaginertia="0.0025599 0.0025599 0.0021942"/>
                            <joint name="right_wrist_1_joint"/>
                            <geom mesh="wrist1_0" material="black" class="visual"/>
                            <geom mesh="wrist1_1" material="urblue" class="visual"/>
                            <geom mesh="wrist1_2" material="jointgray" class="visual"/>
                            <geom class="collision" pos="0 0.05 0" quat="1 1 0 0" size="0.04 0.07"/>
                            <body name="right_wrist_2_link" pos="0 0.127 0">
                                <inertial mass="1.219" pos="0 0 0.1" diaginertia="0.0025599 0.0025599 0.0021942"/>
                                <joint name="right_wrist_2_joint" axis="0 0 1"/>
                                <geom mesh="wrist2_0" material="black" class="visual"/>
                                <geom mesh="wrist2_1" material="urblue" class="visual"/>
                                <geom mesh="wrist2_2" material="jointgray" class="visual"/>
                                <geom class="collision" size="0.04 0.06" pos="0 0 0.04"/>
                                <geom class="collision" pos="0 0.02 0.1" quat="1 1 0 0" size="0.04 0.04"/>
                                <body name="right_wrist_3_link" pos="0 0 0.1">
                                    <inertial mass="0.1879" pos="0 0.0771683 0" quat="1 0 0 1" diaginertia="0.000132134 9.90863e-05 9.90863e-05"/>
                                    <joint name="right_wrist_3_joint"/>
                                    <geom material="linkgray" mesh="wrist3" class="visual"/>
                                    <geom class="eef_collision" pos="0 0.08 0" quat="1 1 0 0" size="0.04 0.02"/>
                                    <site name="right_attachment_site" size="0.01" pos="0 0.1 0" quat="-1 1 1 1" rgba="1 0 0 1" group="1"/>
                                    <body name="right_tool0" pos="0 0.1 0" quat="0.70710678 -0.70710678 0 0">
                                        <geom name="right_tool0_x_shaft" type="cylinder" size="0.005 0.05" pos="0.05 0 0" zaxis="1 0 0" rgba="1 0 0 1" contype="0" conaffinity="0" group="1" class="visual"/>
                                        <geom name="right_tool0_y_shaft" type="cylinder" size="0.005 0.05" pos="0 0.05 0" zaxis="0 1 0" rgba="0 1 0 1" contype="0" conaffinity="0" group="1" class="visual"/>
                                        <geom name="right_tool0_z_shaft" type="cylinder" size="0.005 0.05" pos="0 0 0.05" zaxis="0 0 1" rgba="0 0 1 1" contype="0" conaffinity="0" group="1" class="visual"/>
                                        <site name="right_tool0_site" size="0.01" pos="0 0 0" rgba="0 1 0 1" group="1"/>
                                    </body>
                                </body>
                            </body>
                        </body>
                    </body>
                </body>
            </body>
        </body>


    </worldbody>

    <actuator>
        <!-- Left Arm Actuators -->
        <position class="position" name="left_shoulder_pan_joint" joint="left_shoulder_pan_joint"/>
        <position class="position" name="left_shoulder_lift_joint" joint="left_shoulder_lift_joint"/>
        <position class="position_limited" name="left_elbow_joint" joint="left_elbow_joint"/>
        <position class="position_small" name="left_wrist_1_joint" joint="left_wrist_1_joint"/>
        <position class="position_small" name="left_wrist_2_joint" joint="left_wrist_2_joint"/>
        <position class="position_small" name="left_wrist_3_joint" joint="left_wrist_3_joint"/>
        <!-- Right Arm Actuators -->
        <position class="position" name="right_shoulder_pan_joint" joint="right_shoulder_pan_joint"/>
        <position class="position" name="right_shoulder_lift_joint" joint="right_shoulder_lift_joint"/>
        <position class="position_limited" name="right_elbow_joint" joint="right_elbow_joint"/>
        <position class="position_small" name="right_wrist_1_joint" joint="right_wrist_1_joint"/>
        <position class="position_small" name="right_wrist_2_joint" joint="right_wrist_2_joint"/>
        <position class="position_small" name="right_wrist_3_joint" joint="right_wrist_3_joint"/>
    </actuator>

    <keyframe>
        <key name="home"
                 qpos="2.88433112 -0.82903139  2.07572008 -0.67998028  1.52733763  2.61031443 3.3777357  -2.86530703 -1.99002441  1.0124655   1.77796691 -2.41553568"
                 ctrl="2.88433112 -0.82903139  2.07572008 -0.67998028  1.52733763  2.61031443 3.3777357  -2.86530703 -1.99002441  1.0124655   1.77796691 -2.41553568"/>
        <key name="zero"
                 qpos="0 0 0 0 0 0 0 0 0 0 0 0"
                 ctrl="0 0 0 0 0 0 0 0 0 0 0 0"/>
    </keyframe>
</mujoco>